<?xml version="1.0"?>
<robot name="coover_arm">
    <link name="link_0">
        <visual>
            <origin xyz="0 0 0" rpy="0 0 0" />
            <geometry>
                <!-- <mesh filename="package://coover_arm_description/meshes/link_0.dae" /> -->
                <mesh filename="package://coover_arm_description/meshes/mm/link_0.stl" scale ="0.001 0.001 0.001"/>
            </geometry>
        </visual>
        <collision>
            <origin xyz="0 0 0" rpy="0 0 0" />
            <geometry>
                <!-- <mesh filename="package://coover_arm_description/meshes/link_0.dae"/> -->
                <mesh filename="package://coover_arm_description/meshes/mm/link_0.stl" scale ="0.001 0.001 0.001"/>
            </geometry>
        </collision>
    </link>

    <link name="link_1">
        <visual>
            <origin xyz="0 0 0" rpy="0 0 0" />
            <geometry>
                <!-- <mesh filename="package://coover_arm_description/meshes/link_1.dae"/> -->
                <mesh filename="package://coover_arm_description/meshes/mm/link_1.stl" scale ="0.001 0.001 0.001"/>
            </geometry>
             <material name="green"/>
        </visual>
        <collision>
            <origin xyz="0 0 0" rpy="0 0 0" />
            <geometry>
                <!-- <mesh filename="package://coover_arm_description/meshes/link_1.dae"/> -->
                <mesh filename="package://coover_arm_description/meshes/mm/link_1.stl" scale ="0.001 0.001 0.001"/>
            </geometry>
        </collision>
    </link>

    <link name="link_2">
        <visual>
            <origin xyz="0 0 0" rpy="0 0 0" />
            <geometry>
                <!-- <mesh filename="package://coover_arm_description/meshes/link_2.dae"/> -->
                <mesh filename="package://coover_arm_description/meshes/mm/link_2.stl" scale ="0.001 0.001 0.001"/>
            </geometry>
        </visual>
        <collision>
            <origin xyz="0 0 0" rpy="0 0 0" />
            <geometry>
                <!-- <mesh filename="package://coover_arm_description/meshes/link_2.dae"/> -->
                <mesh filename="package://coover_arm_description/meshes/mm/link_2.stl" scale ="0.001 0.001 0.001"/>
            </geometry>
        </collision>
    </link>

    <link name="link_3">
        <visual>
            <origin xyz="0 0 0" rpy="0 0 0" />
            <geometry>
                <!-- <mesh filename="package://coover_arm_description/meshes/link_3.dae"/> -->
                <mesh filename="package://coover_arm_description/meshes/mm/link_3.stl" scale ="0.001 0.001 0.001"/>
            </geometry>
        </visual>
        <collision>
            <origin xyz="0 0 0" rpy="0 0 0" />
            <geometry>
                <!-- <mesh filename="package://coover_arm_description/meshes/link_3.dae"/> -->
                <mesh filename="package://coover_arm_description/meshes/mm/link_3.stl" scale ="0.001 0.001 0.001"/>
            </geometry>
        </collision>
    </link>

    <link name="link_4">
        <visual>
            <origin xyz="0 0 0" rpy="0 0 0" />
            <geometry>
                <!-- <mesh filename="package://coover_arm_description/meshes/link_4.dae"/> -->
                <mesh filename="package://coover_arm_description/meshes/mm/link_4.stl" scale ="0.001 0.001 0.001"/>
            </geometry>
        </visual>
        <collision>
            <origin xyz="0 0 0" rpy="0 0 0" />
            <geometry>
                <!-- <mesh filename="package://coover_arm_description/meshes/link_4.dae"/> -->
                <mesh filename="package://coover_arm_description/meshes/mm/link_4.stl" scale ="0.001 0.001 0.001"/>
            </geometry>
        </collision>
    </link>

    <link name="link_5">
        <visual>
            <origin xyz="0 0 0" rpy="0 0 0" />
            <geometry>
                <!-- <mesh filename="package://coover_arm_description/meshes/link_5.dae"/> -->
                <mesh filename="package://coover_arm_description/meshes/mm/link_5.stl" scale ="0.001 0.001 0.001"/>
            </geometry>
        </visual>
        <collision>
            <origin xyz="0 0 0" rpy="0 0 0" />
            <geometry>
                <!-- <mesh filename="package://coover_arm_description/meshes/link_5.dae"/> -->
                <mesh filename="package://coover_arm_description/meshes/mm/link_5.stl" scale ="0.001 0.001 0.001"/>
            </geometry>
        </collision>
    </link>

    <link name="link_6">
        <visual>
            <origin xyz="0 0 0" rpy="0 0 0" />
            <geometry>
                <box size="0.001 0.001 0.001" />
            </geometry>
        </visual>
        <collision>
            <origin xyz="0 0 0" rpy="0 0 0" />
            <geometry>
                <box size="0.001 0.001 0.001" />
            </geometry>
        </collision>
    </link>

    <joint name="joint_0" type="fixed">
        <parent link="link_0" />
        <child link="link_1" />
        <origin xyz="0 0 0.045" rpy="0 0 0" />
        
    </joint>

    <joint name="joint_1" type="revolute">
        <origin xyz="0 0 0" rpy="0 0 0" />
        <axis xyz="0 0 1" />
        <parent link="link_1"/>
        <child link="link_2"/>
        <limit effort="1000.0" lower="-1.708" upper="1.708" velocity="1.0" />
    </joint>

    <joint name="joint_2" type="revolute">
        <origin xyz="0 0 0.0415" rpy="0 0 0" />
        <axis xyz="0 1 0" />
        <parent link="link_2"/>
        <child link="link_3"/>
        <limit effort="1000.0" lower="-1.708" upper="1.708" velocity="1.0" />
    </joint>

    <joint name="joint_3" type="revolute">
        <origin xyz="0.043 0 0.174" rpy="0 0 0" />
        <axis xyz="0 1 0" />
        <parent link="link_3"/>
        <child link="link_4"/>
        <limit effort="1000.0" lower="-0.1" upper="3.14" velocity="1.0" />
    </joint>

    <joint name="joint_4" type="revolute">
        <origin xyz="0.0099 0 0.1415" rpy="0 0 0" />
        <axis xyz="0 1 0" />
        <parent link="link_4"/>
        <child link="link_5"/>
        <limit effort="1000.0" lower="-1.708" upper="1.708" velocity="1.0" />
    </joint>

    <joint name="joint_5" type="fixed">
    <parent link="link_5" />
    <child link="link_6" />
    <origin xyz="0 0 0.048" rpy="0 -1.57 0" />
  </joint>

</robot>