<?xml version="1.0"?>
<robot name="campusrover_arm">

    <link name="arm_link_1">
        <visual>
            <origin xyz="0 0 0" rpy="0 0 0" />
            <geometry>
                <!-- <mesh filename="package://campusrover_arm_description/meshes/link_1.dae"/> -->
                <mesh filename="package://campusrover_arm_description/meshes/arm_link_1.stl" scale ="0.001 0.001 0.001"/>
            </geometry>
             <material name="green"/>
        </visual>
        <collision>
            <origin xyz="0 0 0" rpy="0 0 0" />
            <geometry>
                <!-- <mesh filename="package://campusrover_arm_description/meshes/link_1.dae"/> -->
                <mesh filename="package://campusrover_arm_description/meshes/arm_link_1.stl" scale ="0.001 0.001 0.001"/>
            </geometry>
        </collision>
    </link>

    <link name="arm_link_2">
        <visual>
            <origin xyz="0 0 0" rpy="0 0 0" />
            <geometry>
                <!-- <mesh filename="package://campusrover_arm_description/meshes/link_2.dae"/> -->
                <mesh filename="package://campusrover_arm_description/meshes/arm_link_2.stl" scale ="0.001 0.001 0.001"/>
            </geometry>
        </visual>
        <collision>
            <origin xyz="0 0 0" rpy="0 0 0" />
            <geometry>
                <!-- <mesh filename="package://campusrover_arm_description/meshes/link_2.dae"/> -->
                <mesh filename="package://campusrover_arm_description/meshes/arm_link_2.stl" scale ="0.001 0.001 0.001"/>
            </geometry>
        </collision>
    </link>

    <link name="arm_link_3">
        <visual>
            <origin xyz="0 0 0" rpy="0 0 0" />
            <geometry>
                <!-- <mesh filename="package://campusrover_arm_description/meshes/link_3.dae"/> -->
                <mesh filename="package://campusrover_arm_description/meshes/arm_link_3.stl" scale ="0.001 0.001 0.001"/>
            </geometry>
        </visual>
        <collision>
            <origin xyz="0 0 0" rpy="0 0 0" />
            <geometry>
                <!-- <mesh filename="package://campusrover_arm_description/meshes/link_3.dae"/> -->
                <mesh filename="package://campusrover_arm_description/meshes/arm_link_3.stl" scale ="0.001 0.001 0.001"/>
            </geometry>
        </collision>
    </link>

    <link name="arm_link_4">
        <visual>
            <origin xyz="0 0 0" rpy="0 0 0" />
            <geometry>
                <!-- <mesh filename="package://campusrover_arm_description/meshes/link_4.dae"/> -->
                <mesh filename="package://campusrover_arm_description/meshes/arm_link_4.stl" scale ="0.001 0.001 0.001"/>
            </geometry>
        </visual>
        <collision>
            <origin xyz="0 0 0" rpy="0 0 0" />
            <geometry>
                <!-- <mesh filename="package://campusrover_arm_description/meshes/link_4.dae"/> -->
                <mesh filename="package://campusrover_arm_description/meshes/arm_link_4.stl" scale ="0.001 0.001 0.001"/>
            </geometry>
        </collision>
    </link>

    <link name="arm_link_5">
        <visual>
            <origin xyz="0 0 0" rpy="0 0 0" />
            <geometry>
                <!-- <mesh filename="package://campusrover_arm_description/meshes/link_5.dae"/> -->
                <mesh filename="package://campusrover_arm_description/meshes/arm_link_5.stl" scale ="0.001 0.001 0.001"/>
            </geometry>
        </visual>
        <collision>
            <origin xyz="0 0 0" rpy="0 0 0" />
            <geometry>
                <!-- <mesh filename="package://campusrover_arm_description/meshes/link_5.dae"/> -->
                <mesh filename="package://campusrover_arm_description/meshes/arm_link_5.stl" scale ="0.001 0.001 0.001"/>
            </geometry>
        </collision>
    </link>

    <link name="arm_link_6">
        <visual>
            <origin xyz="0 0 0" rpy="0 0 0" />
            <geometry>
                <box size="0.001 0.001 0.001" />
            </geometry>
        </visual>
        <collision>
            <origin xyz="0 0 0" rpy="0 0 0" />
            <geometry>
                <box size="0.001 0.001 0.001" />
            </geometry>
        </collision>
    </link>

    <joint name="joint_1" type="revolute">
        <origin xyz="0 0 0" rpy="0 0 0" />
        <axis xyz="0 0 1" />
        <parent link="arm_link_1"/>
        <child link="arm_link_2"/>
        <limit effort="1000.0" lower="-1.708" upper="1.708" velocity="1.0" />
    </joint>

    <joint name="joint_2" type="revolute">
        <origin xyz="0 0 0.026" rpy="0 0 0" />
        <axis xyz="0 1 0" />
        <parent link="arm_link_2"/>
        <child link="arm_link_3"/>
        <limit effort="1000.0" lower="-1.57" upper="1.57" velocity="1.0" />
    </joint>

    <joint name="joint_3" type="revolute">
        <origin xyz="0.00 0 0.1595" rpy="0 0 0" />
        <axis xyz="0 1 0" />
        <parent link="arm_link_3"/>
        <child link="arm_link_4"/>
        <limit effort="1000.0" lower="-1.57" upper="1.57" velocity="1.0" />
    </joint>

    <joint name="joint_4" type="revolute">
        <origin xyz="0.0675 0 0.0" rpy="0 0 0" />
        <axis xyz="0 1 0" />
        <parent link="arm_link_4"/>
        <child link="arm_link_5"/>
        <limit effort="1000.0" lower="-1.708" upper="1.708" velocity="1.0" />
    </joint>

    <joint name="joint_5" type="fixed">
        <parent link="arm_link_5" />
        <child link="arm_link_6" />
        <origin xyz="0.0405 0 0" rpy="0 -1.57 0" />
    </joint>

</robot>